<!-- lwa3_hand.urdf -->

<robot name="lwa3">

  <!-- Link 0 -->
  <link name = "L0">
    <visual>
	    <geometry>
		    <mesh filename="schunk/l0.3ds" />
		  </geometry>
	  </visual>
  </link> 	

	<!-- Link 1 -->
	<link name = "L1">
		<visual>
			<geometry>
				<mesh filename="schunk/l1.3ds" />
			</geometry>
		</visual>
	</link> 	

	<!-- Link 2 -->
	<link name = "L2">
		<visual>
			<geometry>
				<mesh filename="schunk/l2.3ds" />
			</geometry>
		</visual>
	</link> 	

	<!-- Link 3 -->
	<link name = "L3">
		<visual>
			<geometry>
				<mesh filename="schunk/l3.3ds" />
			</geometry>
		</visual>
	</link> 	

	<!-- Link 4 -->
	<link name = "L4">
		<visual>
			<geometry>
				<mesh filename="schunk/l4.3ds" />
			</geometry>
		</visual>
	</link> 	

	<!-- Link 5 -->
	<link name = "L5">
		<visual>
			<geometry>
				<mesh filename="schunk/l5.3ds" />
			</geometry>
		</visual>
	</link> 	

	<!-- Link 6 -->
	<link name = "L6">
		<visual>
			<geometry>
				<mesh filename="schunk/l6.3ds" />
			</geometry>
		</visual>
	</link> 	

	<!-- Link ftsensor -->
	<link name = "FT">
		<visual>
			<geometry>
				<mesh filename="schunk/ft.3ds" />
			</geometry>
		</visual>
	</link> 

<!-- Link hand -->
	<link name = "HAND">
		<visual>
			<geometry>
				<mesh filename="schunk/handbase66.3ds" />
			</geometry>
		</visual>
	</link> 

	<!-- Link F11 -->
	<link name = "F11">
		<visual>
			<geometry>
				<mesh filename="schunk/handjoint66.3ds"/>
			</geometry>
		</visual>
	</link> 	

	<!-- Link F12 -->
	<link name = "F12">
		<visual>
			<geometry>
				<mesh filename="schunk/finger66.3ds"/>
			</geometry>
		</visual>
	</link> 	

<!-- Link F13 -->
	<link name = "F13">
		<visual>
			<geometry>
				<mesh filename="schunk/fingertip66.3ds" />
			</geometry>
		</visual>
	</link> 	

	<!-- Link F21 -->
	<link name = "F21">
		<visual>
			<geometry>
				<mesh filename="schunk/handjoint66.3ds"/>
			</geometry>
		</visual>
	</link> 	

	<!-- Link F22 -->
	<link name = "F22">
		<visual>
			<geometry>
				<mesh filename="schunk/finger66.3ds"/>
			</geometry>
		</visual>
	</link> 	

<!-- Link F23 -->
	<link name = "F23">
		<visual>
			<geometry>
				<mesh filename="schunk/fingertip66.3ds" />
			</geometry>
		</visual>
	</link> 	

	<!-- Link F31 -->
	<link name = "F31">
		<visual>
			<geometry>
				<mesh filename="schunk/handjoint66.3ds" />
			</geometry>
		</visual>
	</link> 	

	

	<!-- Link F32 -->
	<link name = "F32">
		<visual>
			<geometry>
				<mesh filename="schunk/finger66.3ds" />
			</geometry>
		</visual>
	</link> 	



	<!-- Link F33 -->
	<link name = "F33">
		<visual>
			<geometry>
				<mesh filename="schunk/fingertip66.3ds" />
			</geometry>
		</visual>
	</link> 	




	<!-- JOINT DEFINITIONS -->

	<!-- J1 -->
	<joint name="J1" type="revolute">
		<parent link="L0" />
		<child link="L1" />
		<origin xyz = "-0.3 0 0" rpy="0 0 0" />
		<axis xyz="1 0 0" />
		<limit effort="1000" lower="-3.1416" upper="3.1416" velocity="0.1" />
	</joint>

	<!-- J2 -->
	<joint name="J2" type="revolute">
		<parent link="L1" />
		<child link="L2" />
		<origin xyz="0 0 0" rpy="0 0 0" />
		<axis xyz="0 1 0" />
		<limit effort="1000" lower="-2.094" upper="2.094" velocity="0.1" />
	</joint>

	<!-- J3 -->
	<joint name="J3" type="revolute">
		<parent link="L2" />
		<child link="L3" />
		<origin xyz="-0.328 0 0" rpy="0 0 0" />
		<axis xyz="1 0 0" />
		<limit effort="1000" lower="-3.1416" upper="3.1416" velocity="0.1" />
	</joint>

	<!-- J4 -->
	<joint name="J4" type="revolute">
		<parent link="L3" />
		<child link="L4" />
		<origin xyz="0 0 0" rpy="0 0 0" />
		<axis xyz="0 1 0" />
		<limit effort="1000" lower="-2.094" upper="2.094" velocity="0.1" />
	</joint>

	<!-- J5 -->
	<joint name="J5" type="revolute">
		<parent link="L4" />
		<child link="L5" />
		<origin xyz="-0.2765 0 0" rpy="0 0 0" />
		<axis xyz="1 0 0" />
		<limit effort="1000" lower="-3.1416" upper="3.1416" velocity="0.1" />
	</joint>

	<!-- J6 -->
	<joint name="J6" type="revolute">
		<parent link="L5" />
		<child link="L6" />
		<origin xyz="0 0 0" rpy="0 0 0" />
		<axis xyz="0 1 0" />
		<limit effort="1000" lower="-2.094" upper="2.094" velocity="0.1" />
	</joint>

	<!-- J7 -->
	<joint name="J7" type="revolute">
		<parent link="L6" />
		<child link="FT"/>
		<origin xyz="-0.2 0 0" rpy="0 0 0" />
		<axis xyz="1 0 0" />
		<limit effort="1000" lower="-3.1416" upper="3.1416" velocity="0.1" />
	</joint>


  <!-- FT - HAND JOINT (WRIST) -->

	<!-- JH0 -->
	<joint name="JH0" type="fixed">
		<parent link="FT" />
		<child link="HAND" />
		<origin xyz="-0.018 0 0" rpy="0 0 0" />
		<axis xyz="0 0 1" />
		<limit effort="1000" lower="-3.1416" upper="3.1416" velocity="0.1" />
	</joint>	

  <!-- HAND - FIRST FINGER JOINTS -->

	<!-- JH11 -->
	<joint name="JH11" type="revolute">
		<parent link="HAND"/>
		<child link="F11"/>
		<origin xyz="-0.024 0.033 0.021" rpy="0 0 0"/>
		<axis xyz="1 0 0" />
		<limit effort="1000" lower="-3.1416" upper="3.1416" velocity="0.1" />
	</joint>

	<!-- JH12 -->
	<joint name="JH12" type="revolute">
		<parent link="F11"/>
		<child link="F12"/>
		<origin xyz="-0.02 0.0 0.0" rpy="0 0 0"/>
		<axis xyz="0 1 0"/>
		<limit effort="1000" lower="-3.1416" upper="3.1416" velocity="0.1"/>
	</joint> 

	<!-- JH13 -->
	<joint name="JH13" type="revolute">
		<parent link="F12" />
		<child link="F13" />
		<origin xyz="-0.0865 0.0 0.0" rpy="0 0 0" />
		<axis xyz="0 1 0" />
		<limit effort="1000" lower="-3.1416" upper="3.1416" velocity="0.1" />
	</joint>

	<!-- JH21 -->
	<joint name="JH21" type="revolute">
		<parent link="HAND" />
		<child link="F21" />
		<origin xyz="-0.024 -0.033 0.021" rpy="0 0 0" />
		<axis xyz="1 0 0" />
		<limit effort="1000" lower="-3.1416" upper="3.1416" velocity="0.1" />
	</joint>

	<!-- JH22 -->
	<joint name="JH22" type="revolute">
		<parent link="F21" />
		<child link="F22" />
		<origin xyz="-0.02 0.0 0.0" rpy="0 0 0" />
		<axis xyz="0 1 0" />
		<limit effort="1000" lower="-3.1416" upper="3.1416" velocity="0.1" />
	</joint>

	<!-- JH23 -->
	<joint name="JH23" type="revolute">
		<parent link="F22" />
		<child link="F23" />
		<origin xyz="-0.0865 0.0 0.0" rpy="0 0 0" />
		<axis xyz="0 1 0" />
		<limit effort="1000" lower="-3.1416" upper="3.1416" velocity="0.1" />
	</joint>

	<!-- JH31 -->
	<joint name="JH31" type="revolute">
		<parent link="HAND" />
		<child link="F31" />
		<origin xyz="-0.024 0.0 -0.0381" rpy="0 0 0" />
		<axis xyz="1 0 0" />
		<limit effort="1000" lower="-3.1416" upper="3.1416" velocity="0.1" />
	</joint>

	<!-- JH32 -->
	<joint name="JH32" type="revolute">
		<parent link="F31" />
		<child link="F32" />
		<origin xyz="-0.02 0.0 0.0" rpy="0 0 0" />
		<axis xyz="0 1 0" />
		<limit effort="1000" lower="-3.1416" upper="3.1416" velocity="0.1" />
	</joint>


	<!-- JH33 -->
	<joint name="JH33" type="revolute">
		<parent link="F32" />
		<child link="F33" />
		<origin xyz="-0.0865 0.0 0.0" rpy="0 0 0" />
		<axis xyz="0 1 0" />
		<limit effort="1000" lower="-3.1416" upper="3.1416" velocity="0.1" />
	</joint>


</robot>
